<robot name="rosbot" 
  xmlns:xacro="http://www.ros.org/wiki/xacro">

  <xacro:arg name="robot_namespace" default=""/>
  <xacro:property name="cameraSize" value="0.05"/>
  <xacro:property name="cameraMass" value="0.1"/>
  <xacro:property name="namespace" value="$(arg robot_namespace)" />
  <xacro:include filename="components.xacro" />

  <link name='base_link'>
    <pose>0 0 0 0 0 0</pose>
    <inertial>
      <mass value="2.5"/>
      <origin xyz="0 0 -0.03" rpy="0 0 0"/>
      <inertia ixx="0.1" ixy="0.01" ixz="0.01" iyy="0.1" iyz="0.01" izz="0.1" />
    </inertial>
    <collision name='collision'>
      <origin xyz="0 0 0" rpy="0 0 0"/>
      <geometry>
        <box size="0.20 0.15 0.06"/>
      </geometry>
    </collision>
    <visual name='base_link_visual'>
      <origin xyz="0 0 0" rpy=" 0 0 0"/>
      <geometry>
        <box size="0.20 0.15 0.06"/>
      </geometry>
    </visual>
  </link>

  <link name="front_left_wheel">
    <collision name="collision">
      <origin xyz="0 0 0" rpy="0 0 0"/>
      <geometry>
        <cylinder radius="0.04" length="0.04"/>
      </geometry>
      <surface>
        <friction>
          <ode>
            <mu>0.05</mu>
            <mu2>0.05</mu2>
          </ode>
        </friction>
      </surface>
    </collision>
    <visual name="front_left_wheel_visual">
      <origin xyz="0 0 0" rpy="0 0 0"/>
      <geometry>
        <cylinder radius="0.04" length="0.04"/>
      </geometry>
    </visual>
    <inertial>
      <origin xyz="0 0 0" rpy="0 0 0"/>
      <mass value="0.01"/>
      <inertia ixx="0.001" ixy="0.0001" ixz="0.0001" iyy="0.001" iyz="0.0001" izz="0.001"/>
    </inertial>
  </link>
  <joint type="continuous" name="front_left_wheel_hinge">
    <origin xyz="0.05 0.1 -0.01" rpy="1.57 0 0"/>
    <child link="front_left_wheel"/>
    <parent link="base_link"/>
    <axis xyz="0 0 -1" rpy="0 0 0"/>
    <limit effort="0.1" velocity="1"/>
    <joint_properties damping="0.01" friction="0.005"/>
  </joint>
  <transmission name="front_left_wheel_trans" type="SimpleTransmission">
    <type>transmission_interface/SimpleTransmission</type>
    <actuator name="front_left_wheel_motor">
      <mechanicalReduction>1</mechanicalReduction>
    </actuator>
    <joint name="front_left_wheel_hinge">
      <hardwareInterface>hardware_interface/EffortJointInterface</hardwareInterface>
    </joint>
  </transmission>

  <link name="front_right_wheel">
    <collision name="collision">
      <origin xyz="0 0 0" rpy="0 0 0"/>
      <geometry>
        <cylinder radius="0.04" length="0.04"/>
      </geometry>
      <surface>
        <friction>
          <ode>
            <mu>0.05</mu>
            <mu2>0.05</mu2>
          </ode>
        </friction>
      </surface>
    </collision>
    <visual name="front_right_wheel_visual">
      <origin xyz="0 0 0" rpy="0 0 0"/>
      <geometry>
        <cylinder radius="0.04" length="0.04"/>
      </geometry>
    </visual>
    <inertial>
      <origin xyz="0 0 0" rpy="0 0 0"/>
      <mass value="0.01"/>
      <inertia ixx="0.001" ixy="0.0001" ixz="0.0001" iyy="0.001" iyz="0.0001" izz="0.001"/>
    </inertial>
  </link>
  <joint type="continuous" name="front_right_wheel_hinge">
    <origin xyz="0.05 -0.1 -0.01" rpy="1.5707 0 0"/>
    <child link="front_right_wheel"/>
    <parent link="base_link"/>
    <axis xyz="0 0 -1" rpy="0 0 0"/>
    <limit effort="0.1" velocity="1"/>
    <joint_properties damping="0.01" friction="0.005"/>
  </joint>
  <transmission name="front_right_wheel_trans" type="SimpleTransmission">
    <type>transmission_interface/SimpleTransmission</type>
    <actuator name="front_right_wheel_motor">
      <mechanicalReduction>1</mechanicalReduction>
    </actuator>
    <joint name="front_right_wheel_hinge">
      <hardwareInterface>hardware_interface/EffortJointInterface</hardwareInterface>
    </joint>
  </transmission>

  <link name="rear_left_wheel">
    <collision name="collision">
      <origin xyz="0 0 0" rpy="0 0 0"/>
      <geometry>
        <cylinder radius="0.04" length="0.04"/>
      </geometry>
      <surface>
        <friction>
          <ode>
            <mu>0.05</mu>
            <mu2>0.05</mu2>
          </ode>
        </friction>
      </surface>
    </collision>
    <visual name="rear_left_wheel_visual">
      <origin xyz="0 0 0" rpy="0 0 0"/>
      <geometry>
        <cylinder radius="0.04" length="0.04"/>
      </geometry>
    </visual>
    <inertial>
      <origin xyz="0 0 0" rpy="0 0 0"/>
      <mass value="0.01"/>
      <inertia ixx="0.001" ixy="0.0001" ixz="0.0001" iyy="0.001" iyz="0.0001" izz="0.001"/>
    </inertial>
  </link>
  <joint type="continuous" name="rear_left_wheel_hinge">
    <origin xyz="-0.05 0.1 -0.01" rpy="1.5707 0 0"/>
    <child link="rear_left_wheel"/>
    <parent link="base_link"/>
    <axis xyz="0 0 -1" rpy="0 0 0"/>
    <limit effort="0.1" velocity="1"/>
    <joint_properties damping="0.01" friction="0.005"/>
  </joint>
  <transmission name="rear_left_wheel_trans" type="SimpleTransmission">
    <type>transmission_interface/SimpleTransmission</type>
    <actuator name="rear_left_wheel_motor">
      <mechanicalReduction>1</mechanicalReduction>
    </actuator>
    <joint name="rear_left_wheel_hinge">
      <hardwareInterface>hardware_interface/EffortJointInterface</hardwareInterface>
    </joint>
  </transmission>

  <link name="rear_right_wheel">
    <collision name="collision">
      <origin xyz="0 0 0" rpy="0 0 -0"/>
      <geometry>
        <cylinder radius="0.04" length="0.04"/>
      </geometry>
      <surface>
        <friction>
          <ode>
            <mu>0.05</mu>
            <mu2>0.05</mu2>
          </ode>
        </friction>
      </surface>
    </collision>
    <visual name="rear_right_wheel_visual">
      <origin xyz="0 0 0" rpy="0 0 -0"/>
      <geometry>
        <cylinder radius="0.04" length="0.04"/>
      </geometry>
    </visual>
    <inertial>
      <origin xyz="0 0 0" rpy="0 0 0"/>
      <mass value="0.01"/>
      <inertia ixx="0.001" ixy="0.0001" ixz="0.0001" iyy="0.001" iyz="0.0001" izz="0.001"/>
    </inertial>
  </link>
  <joint type="continuous" name="rear_right_wheel_hinge">
    <origin xyz="-0.05 -0.1 -0.01" rpy="1.5707 0 0"/>
    <child link="rear_right_wheel"/>
    <parent link="base_link"/>
    <axis xyz="0 0 -1" rpy="0 0 0"/>
    <limit effort="0.1" velocity="1"/>
    <joint_properties damping="0.01" friction="0.005"/>
  </joint>
  <transmission name="rear_right_wheel_trans" type="SimpleTransmission">
    <type>transmission_interface/SimpleTransmission</type>
    <actuator name="rear_right_wheel_motor">
      <mechanicalReduction>1</mechanicalReduction>
    </actuator>
    <joint name="rear_right_wheel_hinge">
      <hardwareInterface>hardware_interface/EffortJointInterface</hardwareInterface>
    </joint>
  </transmission>

  <!-- Orbbec Astra RGBD Camera -->
  <joint name="astra_joint" type="fixed">
    <axis xyz="0 0 0" />
    <origin xyz="-0.03 0 0.11" rpy="0 0 0"/>
    <parent link="base_link"/>
    <child link="camera_link"/>
  </joint>
  <link name="camera_link">
    <collision>
      <origin xyz="0 0 0" rpy="0 0 0"/>
      <geometry>
        <box size="0.03 0.1 0.025"/>
      </geometry>
    </collision>
    <visual>
      <origin xyz="0 0 0" rpy="0 0 0"/>
      <geometry>
        <box size="0.03 0.1 0.025"/>
      </geometry>
    </visual>
    <inertial>
      <mass value="1e-5" />
      <origin xyz="0 0 0" rpy="0 0 0"/>
      <inertia ixx="0" ixy="0" ixz="0" iyy="0" iyz="0" izz="0" />
    </inertial>
  </link>
  <joint name="camera_optical_joint" type="fixed">
    <origin xyz="0 0 0" rpy="-0 0 -0"/>
    <parent link="camera_link"/>
    <child link="camera_rgb_frame"/>
  </joint>
  <link name="camera_rgb_frame">
  </link>
  <joint name="camera_depth_joint" type="fixed">
    <origin xyz="0 0 0" rpy="0 1.5707 -0"/>
    <parent link="camera_link"/>
    <child link="camera_depth_frame"/>
  </joint>
  <link name="camera_depth_frame">
  </link>

  <!-- rplidar Laser -->
  <joint name="rplidar_joint" type="fixed">
    <axis xyz="0 1 0" />
    <origin xyz="0.02 0 0.0475" rpy="0 0 0"/>
    <parent link="base_link"/>
    <child link="laser"/>
  </joint>
  <link name="laser">
    <collision>
      <origin xyz="0 0 0" rpy="0 0 0"/>
      <geometry>
        <cylinder radius="0.04" length="0.03"/>
      </geometry>
    </collision>
    <visual>
      <origin xyz="0 0 0" rpy="0 0 0"/>
      <geometry>
        <cylinder radius="0.04" length="0.03"/>
      </geometry>
    </visual>
    <inertial>
      <mass value="1e-5" />
      <origin xyz="0 0 0" rpy="0 0 0"/>
      <inertia ixx="0" ixy="0" ixz="0" iyy="0" iyz="0" izz="0" />
    </inertial>
  </link>

  <gazebo reference="laser">
    <sensor type="ray" name="rp_lidar">
      <pose>0 0 0 0 0 0</pose>
      <visualize>true</visualize>
      <update_rate>30</update_rate>
      <ray>
        <scan>
          <horizontal>
            <samples>720</samples>
            <resolution>1</resolution>
            <min_angle>-3.141693</min_angle>
            <max_angle>3.141693</max_angle>
          </horizontal>
        </scan>
        <range>
          <min>0.25</min>
          <max>15.0</max>
          <resolution>0.01</resolution>
        </range>
        <noise>
          <type>gaussian</type>
          <mean>0.0</mean>
          <stddev>0.01</stddev>
        </noise>
      </ray>

      <plugin name="rp_lidar" filename="libgazebo_ros_ray_sensor.so">
        <ros>
          <!-- <namespace>/laser</namespace> -->
          <argument>~/out:=scan</argument>
        </ros>
        <output_type>sensor_msgs/LaserScan</output_type>
        <frameName>laser</frameName>
      </plugin>
    </sensor>
  </gazebo>


  <joint name="range_fl_joint" type="fixed">
    <axis xyz="0 1 0" />
    <origin xyz="0.1 0.05 0.01" rpy="0 0 0.13 "/>
    <parent link="base_link"/>
    <child link="range_fl"/>
  </joint>
  <link name="range_fl"></link>

  <joint name="range_fr_joint" type="fixed">
    <axis xyz="0 1 0" />
    <origin xyz="0.1 -0.05 0.01" rpy="0 0 -0.13 "/>
    <parent link="base_link"/>
    <child link="range_fr"/>
  </joint>
  <link name="range_fr"></link>

  <joint name="range_rl_joint" type="fixed">
    <axis xyz="0 1 0" />
    <origin xyz="-0.1 0.05 0.01" rpy="0 0 3.01 "/>
    <parent link="base_link"/>
    <child link="range_rl"/>
  </joint>
  <link name="range_rl"></link>

  <joint name="range_rr_joint" type="fixed">
    <axis xyz="0 1 0" />
    <origin xyz="-0.1 -0.05 0.01" rpy="0 0 3.27 "/>
    <parent link="base_link"/>
    <child link="range_rr"/>
  </joint>
  <link name="range_rr"></link>

  <gazebo>
    <plugin name='skid_steer_drive' filename='libgazebo_ros_diff_drive.so'>
      <ros>
      </ros>
      <!-- Update rate -->
      <update_rate>50</update_rate>
      <!-- Number of wheel pairs -->
      <num_wheel_pairs>2</num_wheel_pairs>
      <!-- wheels0 -->
      <left_joint>front_left_wheel_hinge</left_joint>
      <right_joint>front_right_wheel_hinge</right_joint>
      <!-- wheels1-->
      <left_joint>rear_left_wheel_hinge</left_joint>
      <right_joint>rear_right_wheel_hinge</right_joint>

      <!-- kinematics -->
      <wheel_separation>0.24</wheel_separation>
      <wheel_separation>0.24</wheel_separation>
      <wheel_diameter>0.08</wheel_diameter>
      <wheel_diameter>0.08</wheel_diameter>

      <!-- limits -->
      <max_wheel_torque>1</max_wheel_torque>
      <max_wheel_acceleration>5</max_wheel_acceleration>

      <!-- output -->
      <publish_odom>true</publish_odom>
      <publish_odom_tf>true</publish_odom_tf>
      <publish_wheel_tf>true</publish_wheel_tf>
      <odometry_frame>odom</odometry_frame>
      <robot_base_frame>base_link</robot_base_frame>

    </plugin>
  </gazebo>

  <gazebo reference="laser">
    <material>Gazebo/Black</material>
  </gazebo>

  <gazebo reference="camera_link">
    <material>Gazebo/Black</material>
  </gazebo>

  <gazebo reference="front_left_wheel">
    <material>Gazebo/Black</material>
  </gazebo>

  <gazebo reference="front_right_wheel">
    <material>Gazebo/Black</material>
  </gazebo>

  <gazebo reference="rear_left_wheel">
    <material>Gazebo/Black</material>
  </gazebo>

  <gazebo reference="rear_right_wheel">
    <material>Gazebo/Black</material>
  </gazebo>

  <gazebo reference="camera_link">
    <sensor type="depth" name="astra_camera">
      <always_on>true</always_on>
      <update_rate>10.0</update_rate>
      <camera name="astra_camera">
        <horizontal_fov>1.3962634</horizontal_fov>
        <image>
          <width>160</width>
          <height>120</height>
          <format>R8G8B8</format>
        </image>
        <clip>
          <near>0.02</near>
          <far>10</far>
        </clip>
        <noise>
          <type>gaussian</type>
          <mean>0.0</mean>
          <stddev>0.007</stddev>
        </noise>
      </camera>
      <plugin name="astra_camera" filename="libgazebo_ros_camera.so">
        <alwaysOn>true</alwaysOn>
        <updateRate>0.0</updateRate>
        <ros>
        </ros>
        <camera_name>camera</camera_name>
        <frame_name>camera_depth_frame</frame_name>
        <hack_baseline>0.07</hack_baseline>
        <min_depth>0.1</min_depth>
        <max_depth>8.0</max_depth>
      </plugin>
    </sensor>
  </gazebo>

</robot>